<?xml version="1.0" ?>
<!-- =================================================================================== -->
<!-- |    This document was autogenerated by xacro from lbr_iiwa_meshfree.urdf.xacro   | -->
<!-- |    EDITING THIS FILE BY HAND IS NOT RECOMMENDED                                 | -->
<!-- =================================================================================== -->
<robot name="lbr_iiwa" xmlns:xacro="http://www.ros.org/wiki/xacro">
  <!-- Import Rviz colors -->
  <material name="Black">
    <color rgba="0.0 0.0 0.0 1.0"/>
  </material>
  <material name="Blue">
    <color rgba="0.0 0.0 0.8 1.0"/>
  </material>
  <material name="Green">
    <color rgba="0.0 0.8 0.0 1.0"/>
  </material>
  <material name="Grey">
    <color rgba="0.2 0.2 0.2 1.0"/>
  </material>
  <material name="Orange">
    <color rgba="1.0 0.423529411765 0.0392156862745 1.0"/>
  </material>
  <material name="Brown">
    <color rgba="0.870588235294 0.811764705882 0.764705882353 1.0"/>
  </material>
  <material name="Red">
    <color rgba="0.8 0.0 0.0 1.0"/>
  </material>
  <material name="White">
    <color rgba="1.0 1.0 1.0 1.0"/>
  </material>
  <!--Import the lbr iiwa macro -->
  <!-- Import all Gazebo-customization elements, including Gazebo colors -->
  <!-- Import Transmissions -->
  <!-- Include Utilities -->
  <!-- The following macros are adapted from the LWR 4 definitions of the RCPRG - https://github.com/RCPRG-ros-pkg/lwr_robot -->
  <!--Little helper macros to define the inertia matrix needed for links.-->
  <!--Cuboid-->
  <!--Cylinder: length is along the y-axis! -->
  <!-- some constants -->
  <!-- <xacro:property name="safety_controller_k_pos" value="100" />
  <xacro:property name="safety_controller_k_vel" value="2" /> -->
  <!-- Import Gazebo plugins -->
  <gazebo>
    <plugin filename="libgazebo_ros_control.so" name="gazebo_ros_controller">
      <robotNamespace>/lbr_iiwa</robotNamespace>
    </plugin>
  </gazebo>
  <!-- Fix to world just for testing -->
  <link name="world"/>
  <!--lbr-->
  <!--joint between {parent} and link_0-->
  <joint name="world_joint" type="fixed">
    <origin rpy="0 0 0" xyz="0 0 0.0"/>
    <parent link="world"/>
    <child link="lbr_iiwa_link_0"/>
  </joint>
  <link name="lbr_iiwa_link_0">
    <inertial>
      <origin rpy="0 0 0" xyz="-0.1 0 0.07"/>
      <mass value="5"/>
      <inertia ixx="0.05" ixy="0" ixz="0" iyy="0.06" iyz="0" izz="0.03"/>
    </inertial>
    <visual>
      <origin rpy="0 0 0" xyz="0 0 0.07875"/>
      <geometry>
        <box size="0.15 0.15 0.1575"/>
      </geometry>
      <material name="Grey"/>
    </visual>
    <collision>
      <origin rpy="0 0 0" xyz="0 0 0.07875"/>
      <geometry>
        <box size="0.15 0.15 0.1575"/>
      </geometry>
      <material name="Grey"/>
    </collision>
    <!--self_collision_checking>
        <origin xyz="0 0 0" rpy="0 0 0"/>
        <geometry>
          <capsule radius="0.15" length="0.25"/>
        </geometry>
      </self_collision_checking-->
  </link>
  <!-- joint between link_0 and link_1 -->
  <joint name="lbr_iiwa_joint_1" type="revolute">
    <parent link="lbr_iiwa_link_0"/>
    <child link="lbr_iiwa_link_1"/>
    <origin rpy="0 0 0" xyz="0 0 0.1575"/>
    <axis xyz="0 0 1"/>
    <limit effort="300" lower="-3.14159265359" upper="3.14159265359" velocity="30"/>
    <!--   <safety_controller soft_lower_limit="${-168 * M_PI / 180}"
           soft_upper_limit="${168 * M_PI / 180}"
           k_position="${safety_controller_k_pos}"
           k_velocity="${safety_controller_k_vel}"/> -->
    <dynamics damping="0.5"/>
  </joint>
  <link name="lbr_iiwa_link_1">
    <inertial>
      <origin rpy="0 0 0" xyz="0 -0.03 0.12"/>
      <mass value="4"/>
      <inertia ixx="0.1" ixy="0" ixz="0" iyy="0.09" iyz="0" izz="0.02"/>
    </inertial>
    <visual>
      <origin rpy="0 0 0" xyz="0 0 0.10125"/>
      <geometry>
        <box size="0.05 0.05 0.2025"/>
      </geometry>
      <material name="Orange"/>
    </visual>
    <collision>
      <origin rpy="0 0 0" xyz="0 0 0.10125"/>
      <geometry>
        <box size="0.05 0.05 0.2025"/>
      </geometry>
      <material name="Orange"/>
    </collision>
  </link>
  <!-- joint between link_1 and link_2 -->
  <joint name="lbr_iiwa_joint_2" type="revolute">
    <parent link="lbr_iiwa_link_1"/>
    <child link="lbr_iiwa_link_2"/>
    <origin rpy="1.57079632679   0 3.14159265359" xyz="0 0 0.2025"/>
    <axis xyz="0 0 1"/>
    <limit effort="300" lower="-2.09439510239" upper="2.09439510239" velocity="30"/>
    <!-- <safety_controller soft_lower_limit="${-118 * PI / 180}"
           soft_upper_limit="${118 * PI / 180}"
           k_position="${safety_controller_k_pos}"
           k_velocity="${safety_controller_k_vel}"/> -->
    <dynamics damping="0.5"/>
  </joint>
  <link name="lbr_iiwa_link_2">
    <inertial>
      <origin rpy="0 0 0" xyz="0.0003 0.059 0.042"/>
      <mass value="4"/>
      <inertia ixx="0.05" ixy="0" ixz="0" iyy="0.018" iyz="0" izz="0.044"/>
    </inertial>
    <visual>
      <origin rpy="0 0 0" xyz="0 0.10225 0"/>
      <geometry>
        <box size="0.05 0.2045 0.05"/>
      </geometry>
      <material name="Orange"/>
    </visual>
    <collision>
      <origin rpy="0 0 0" xyz="0 0.10225 0"/>
      <geometry>
        <box size="0.05 0.2045 0.05"/>
      </geometry>
      <material name="Orange"/>
    </collision>
  </link>
  <!-- joint between link_2 and link_3 -->
  <joint name="lbr_iiwa_joint_3" type="revolute">
    <parent link="lbr_iiwa_link_2"/>
    <child link="lbr_iiwa_link_3"/>
    <origin rpy="1.57079632679 0 3.14159265359" xyz="0 0.2045 0"/>
    <axis xyz="0 1 0"/>
    <limit effort="300" lower="-2.96705972839" upper="2.96705972839" velocity="30"/>
    <!-- <safety_controller soft_lower_limit="${-118 * PI / 180}"
           soft_upper_limit="${118 * PI / 180}"
           k_position="${safety_controller_k_pos}"
           k_velocity="${safety_controller_k_vel}"/> -->
    <dynamics damping="0.5"/>
  </joint>
  <link name="lbr_iiwa_link_3">
    <inertial>
      <origin rpy="0 0 0" xyz="0 0.03 0.13"/>
      <mass value="3"/>
      <inertia ixx="0.08" ixy="0" ixz="0" iyy="0.075" iyz="0" izz="0.01"/>
    </inertial>
    <visual>
      <origin rpy="0 0 0" xyz="0 0 0.10775"/>
      <geometry>
        <box size="0.05 0.05 0.2155"/>
      </geometry>
      <material name="Orange"/>
    </visual>
    <collision>
      <origin rpy="0 0 0" xyz="0 0 0.10775"/>
      <geometry>
        <box size="0.05 0.05 0.2155"/>
      </geometry>
      <material name="Orange"/>
    </collision>
  </link>
  <!--Extensions -->
  <!-- Link0 -->
  <gazebo reference="lbr_iiwa_link_0">
    <material>Gazebo/Grey</material>
    <mu1>0.2</mu1>
    <mu2>0.2</mu2>
  </gazebo>
  <!-- Link1 -->
  <gazebo reference="lbr_iiwa_link_1">
    <material>Gazebo/Orange</material>
    <mu1>0.2</mu1>
    <mu2>0.2</mu2>
  </gazebo>
  <!-- Link2 -->
  <gazebo reference="lbr_iiwa_link_2">
    <material>Gazebo/Orange</material>
    <mu1>0.2</mu1>
    <mu2>0.2</mu2>
  </gazebo>
  <!-- Link3 -->
  <gazebo reference="lbr_iiwa_link_3">
    <material>Gazebo/Orange</material>
    <mu1>0.2</mu1>
    <mu2>0.2</mu2>
  </gazebo>
  <!-- Link4 -->
  <gazebo reference="lbr_iiwa_link_4">
    <material>Gazebo/Orange</material>
    <mu1>0.2</mu1>
    <mu2>0.2</mu2>
  </gazebo>
  <!-- Link5 -->
  <gazebo reference="lbr_iiwa_link_5">
    <material>Gazebo/Orange</material>
    <mu1>0.2</mu1>
    <mu2>0.2</mu2>
  </gazebo>
  <!-- Link6 -->
  <gazebo reference="lbr_iiwa_link_6">
    <material>Gazebo/Orange</material>
    <mu1>0.2</mu1>
    <mu2>0.2</mu2>
  </gazebo>
  <!-- Link7 -->
  <gazebo reference="lbr_iiwa_link_7">
    <material>Gazebo/Grey</material>
    <mu1>0.2</mu1>
    <mu2>0.2</mu2>
  </gazebo>
  <transmission name="lbr_iiwa_tran_1">
    <type>transmission_interface/SimpleTransmission</type>
    <joint name="lbr_iiwa_joint_1">
      <hardwareInterface>EffortJointInterface</hardwareInterface>
    </joint>
    <actuator name="lbr_iiwa_motor_1">
      <hardwareInterface>EffortJointInterface</hardwareInterface>
      <mechanicalReduction>1</mechanicalReduction>
    </actuator>
  </transmission>
  <transmission name="lbr_iiwa_tran_2">
    <type>transmission_interface/SimpleTransmission</type>
    <joint name="lbr_iiwa_joint_2">
      <hardwareInterface>EffortJointInterface</hardwareInterface>
    </joint>
    <actuator name="lbr_iiwa_motor_2">
      <hardwareInterface>EffortJointInterface</hardwareInterface>
      <mechanicalReduction>1</mechanicalReduction>
    </actuator>
  </transmission>
  <transmission name="lbr_iiwa_tran_3">
    <type>transmission_interface/SimpleTransmission</type>
    <joint name="lbr_iiwa_joint_3">
      <hardwareInterface>EffortJointInterface</hardwareInterface>
    </joint>
    <actuator name="lbr_iiwa_motor_3">
      <hardwareInterface>EffortJointInterface</hardwareInterface>
      <mechanicalReduction>1</mechanicalReduction>
    </actuator>
  </transmission>
  <transmission name="lbr_iiwa_tran_4">
    <type>transmission_interface/SimpleTransmission</type>
    <joint name="lbr_iiwa_joint_4">
      <hardwareInterface>EffortJointInterface</hardwareInterface>
    </joint>
    <actuator name="lbr_iiwa_motor_4">
      <hardwareInterface>EffortJointInterface</hardwareInterface>
      <mechanicalReduction>1</mechanicalReduction>
    </actuator>
  </transmission>
  <transmission name="lbr_iiwa_tran_5">
    <type>transmission_interface/SimpleTransmission</type>
    <joint name="lbr_iiwa_joint_5">
      <hardwareInterface>EffortJointInterface</hardwareInterface>
    </joint>
    <actuator name="lbr_iiwa_motor_5">
      <hardwareInterface>EffortJointInterface</hardwareInterface>
      <mechanicalReduction>1</mechanicalReduction>
    </actuator>
  </transmission>
  <transmission name="lbr_iiwa_tran_6">
    <type>transmission_interface/SimpleTransmission</type>
    <joint name="lbr_iiwa_joint_6">
      <hardwareInterface>EffortJointInterface</hardwareInterface>
    </joint>
    <actuator name="lbr_iiwa_motor_6">
      <hardwareInterface>EffortJointInterface</hardwareInterface>
      <mechanicalReduction>1</mechanicalReduction>
    </actuator>
  </transmission>
  <transmission name="lbr_iiwa_tran_7">
    <type>transmission_interface/SimpleTransmission</type>
    <joint name="lbr_iiwa_joint_7">
      <hardwareInterface>EffortJointInterface</hardwareInterface>
    </joint>
    <actuator name="lbr_iiwa_motor_7">
      <hardwareInterface>EffortJointInterface</hardwareInterface>
      <mechanicalReduction>1</mechanicalReduction>
    </actuator>
  </transmission>
</robot>

